#VRML_SIM R2025a utf8

WorldInfo {
  info [
    "A Braitenberg-like world with a type-2 vehicle"
    "Author: Stefano Franchi"
    "Date: 26 August 2013"
    "Updated for Webots R2025a (Z-up): March 2026"
  ]
  title "SF-Homeo - Type 2 Braitenberg-like vehicle"
}
Viewpoint {
  orientation -0.003749962241916675 0.9999852437060718 0.003930668300981131 1.5237647400812049
  position 5.36261109880915 3.1006360374357573 29.23013236934025
}
Background {
  skyColor [
    0.4 0.7 1
  ]
}
DEF TARGET PointLight {
  attenuation 0 0 1
  color 0 1 0
  location 7 7 0.11
}
DirectionalLight {
  ambientIntensity 1
}
DEF LIGHT2 PointLight {
  attenuation 0 0 1
  color 0 1 0
  intensity 0.4
  location 11.6 12.3 0.1
  on FALSE
}
DEF GROUND Solid {
  translation 9.5 9.5 -0.05
  children [
    Shape {
      appearance Appearance {
        material Material {
          diffuseColor 0.803922 0.498039 0.298039
        }
      }
      geometry Box {
        size 20 20 0.1
      }
    }
  ]
  boundingObject Box {
    size 20 20 0.1
  }
}
DEF KHEPERA Robot {
  translation 3.999999992842449 3.999999936126503 0.017435329012312838
  rotation -1.0256977427497007e-07 -1.83637935282612e-06 0.9999999999983086 3.030000000000188
  children [
    Shape {
      appearance Appearance {
        material Material {
          diffuseColor 0.0539951 0.505576 0.0897663
        }
      }
      geometry IndexedFaceSet {
        coord Coordinate {
          point [
            0.0276 -0.009 0.0025, 0.0215 -0.0194 0.0025, 0.0118 -0.0265 0.0025, 0 -0.029 0.0025, -0.0118 -0.0265 0.0025, -0.0215 -0.0194 0.0025, -0.0276 -0.009 0.0025, -0.0236 -0.009 0.02, -0.0236 0.009 0.02, 0.0236 0.009 0.02, 0.0236 -0.009 0.02, -0.0276 0.009 0.0025, -0.0215 0.0194 0.0025, -0.0118 0.0265 0.0025, 0 0.029 0.0025, 0.0118 0.0265 0.0025, 0.0215 0.0194 0.0025, 0.0276 0.009 0.0025, 0.0276 -0.009 0.001, 0.0215 -0.0194 0.001, 0.0118 -0.0265 0.001, 0 -0.029 0.001, -0.0118 -0.0265 0.001, -0.0215 -0.0194 0.001, -0.0276 -0.009 0.001, -0.0236 -0.009 0.001, -0.0236 0.009 0.001, 0.0236 0.009 0.001, 0.0236 -0.009 0.001, -0.0276 0.009 0.001, -0.0215 0.0194 0.001, -0.0118 0.0265 0.001, 0 0.029 0.001, 0.0118 0.0265 0.001, 0.0215 0.0194 0.001, 0.0276 0.009 0.001
          ]
        }
        ccw FALSE
        coordIndex [
          0, 1, 2, 3, 4, 5, 6, -1, 11, 12, 13, 14, 15, 16, 17, -1, 24, 23, 22, 21, 20, 19, 18, -1, 35, 34, 33, 32, 31, 30, 29, -1, 1, 0, 18, 19, -1, 2, 1, 19, 20, -1, 3, 2, 20, 21, -1, 4, 3, 21, 22, -1, 5, 4, 22, 23, -1, 6, 5, 23, 24, -1, 0, 6, 24, 18, -1, 17, 16, 34, 35, -1, 16, 15, 33, 34, -1, 15, 14, 32, 33, -1, 14, 13, 31, 32, -1, 13, 12, 30, 31, -1, 12, 11, 29, 30, -1, 11, 17, 35, 29, -1, 7, 10, 28, 25, -1, 9, 8, 26, 27, -1, 8, 7, 25, 26, -1, 10, 9, 27, 28, -1, 28, 27, 26, 25, -1
        ]
        creaseAngle 0.5
      }
    }
    Pose {
      translation 0 0 0.02
      rotation 1 0 0 1.5708
      children [
        Shape {
          appearance Appearance {
            material Material {
              diffuseColor 0.015 0.48 0.1796
            }
          }
          geometry Cylinder {
            height 0.0015
            radius 0.028
          }
        }
      ]
    }
    HingeJoint {
      jointParameters HingeJointParameters {
        position 3.337005937788627e-17
        axis -1 0 0
        anchor -0.026 0 0.0075
      }
      device [
        RotationalMotor {
          name "left wheel motor"
          maxVelocity 100
        }
        PositionSensor {
          name "left wheel sensor"
        }
      ]
      endPoint Solid {
        translation -0.026 0 0.0075
        rotation 0.9996930990137797 -0.0056977282093818235 0.024108995779109788 5.75626704328828e-16
        children [
          DEF WHEEL Pose {
            rotation 0 0 1 -1.5708
            children [
              Shape {
                appearance Appearance {
                  material Material {
                    diffuseColor 0.778497 0.793743 0.8
                  }
                }
                geometry Cylinder {
                  height 0.003
                  radius 0.0075
                }
              }
            ]
          }
        ]
        name "left wheel"
        boundingObject Pose {
          rotation 0 0 1 -1.5708
          children [
            Cylinder {
              height 0.003
              radius 0.0075
            }
          ]
        }
        physics Physics {
        }
        linearVelocity -7.657821783124799e-12 -6.815720562170591e-11 8.244460249152843e-06
        angularVelocity 2.7263879075683183e-09 -3.0631173718708283e-10 4.2287931240483074e-16
      }
    }
    HingeJoint {
      jointParameters HingeJointParameters {
        position 3.336993482433835e-17
        axis -1 0 0
        anchor 0.026 0 0.0075
      }
      device [
        RotationalMotor {
          name "right wheel motor"
          maxVelocity 100
        }
        PositionSensor {
          name "right wheel sensor"
        }
      ]
      endPoint Solid {
        translation 0.026 0 0.0075
        rotation 0.9983665850080674 -0.006509722315113515 0.05676077390865697 2.4449604770010497e-16
        children [
          USE WHEEL
        ]
        name "right wheel"
        boundingObject Pose {
          rotation 0 0 1 -1.5708
          children [
            Cylinder {
              height 0.003
              radius 0.0075
            }
          ]
        }
        physics Physics {
        }
        linearVelocity -7.65782311140766e-12 -6.815999287579534e-11 8.24446020815986e-06
        angularVelocity 2.72638790936329e-09 -3.063117211339186e-10 4.2715399400909453e-16
      }
    }
    DEF LS0 LightSensor {
      translation -0.0185 -0.021 0.0144
      rotation 0 0 1 2.3562
      name "ls0"
      lookupTable [
        0 1000 0.05
        10 10 0.05
      ]
      colorFilter 0 1 0
    }
    DEF LS1 LightSensor {
      translation 0.0185 -0.021 0.0144
      rotation 0 0 1 0.8
      name "ls1"
      lookupTable [
        0 1000 0.05
        10 10 0.05
      ]
      colorFilter 0 1 0
    }
  ]
  name "khepera"
  model "Unspecified"
  description "A mini mobile robot by K-Team SA"
  boundingObject Pose {
    translation 0 0 0.011
    rotation 1 0 0 1.5708
    children [
      Cylinder {
        height 0.022
        radius 0.0285
      }
    ]
  }
  physics Physics {
    density -1
    mass 0.08
  }
  controller "server-python"
  controllerArgs [
    "10020"
  ]
  linearVelocity -8.729912630821486e-12 -7.770233959269369e-11 8.244468496168327e-06
  angularVelocity 2.7263868529377724e-09 -3.063117843883285e-10 1.6543227371314537e-16
}
DEF TRAJECTORY Robot {
  name "trajRecorder"
  controller "supervisorTrajectory"
  supervisor TRUE
}
DEF SIMULSUPER Robot {
  name "SIMULSUPER"
  controller "server-supervisor-python"
  controllerArgs [
    "10021"
  ]
  supervisor TRUE
}
